Workbook
Name Admin: 'Data Valid.'!$A:$A
Name Aggregate: 'W. Performed'!$M$1:$M$2
Name CD_Thomas: 'W. Performed'!$J:$J
Name DC_Materials: 'W. Performed'!$K:$K
Name Job_1250: 'Data Valid.'!$C:$C
Name Job_1292: 'Data Valid.'!$D:$D
Name Job_1304: 'Data Valid.'!$E:$E
Name Job_1312: 'Data Valid.'!$F:$F
Name Job_1318: 'Data Valid.'!$G:$G
Name Job_1336: 'Data Valid.'!$H:$H
Name Job_1343: 'Data Valid.'!$I:$I
Name Job_1344: 'Data Valid.'!$J:$J
Name Job_1349: 'Data Valid.'!$K:$K
Name Job_1353: 'Data Valid.'!$L:$L
Name Job_1356: 'Data Valid.'!$M:$M
Name Job_1357: 'Data Valid.'!$N:$N
Name Job_1362: 'Data Valid.'!$O:$O
Name Job_1363: 'Data Valid.'!$P:$P
Name Job_1364: 'Data Valid.'!$Q:$Q
Name Job_1368: 'Data Valid.'!$R:$R
Name Job_1369: 'Data Valid.'!$S:$S
Name Job_1370: 'Data Valid.'!$T:$T
Name Job_1371: 'Data Valid.'!$U:$U
Name Job_1372: 'Data Valid.'!$V:$V
Name Job_1378: 'Data Valid.'!$W:$W
Name Job_1379: 'Data Valid.'!$X:$X
Name Job_1381: 'Data Valid.'!$Y:$Y
Name Job_1382: 'Data Valid.'!$Z:$Z
Name Job_1383: 'Data Valid.'!$AA:$AA
Name Job_1386: 'Data Valid.'!$AB:$AB
Name Job_99: 'Data Valid.'!$B:$B
Name LaFarge: 'W. Performed'!$E:$E
Name M_Luis_Products: 'W. Performed'!$F:$F
Name Martin_Marietta: 'W. Performed'!$I:$I
Name MD_Paving: 'W. Performed'!$G:$G
Name People_Ready: 'W. Performed'!$L:$L
Name Pleasants: 'W. Performed'!$H:$H
Name Rowen: 'W. Performed'!$B:$B
Name Schuster_Baltimore: 'W. Performed'!$D:$D
Name Schuster_Rockville: 'W. Performed'!$C:$C
Name Vulcan: 'W. Performed'!$A:$A

Sheet Timesheet
A1: FOREMAN DAILY TIMESHEET | D1: Date: | H1: Shift: | N1: LUNCH: | S1: JOB#:
B3: M LUIS CONSTRUCTION COMPANY 12200 PLUM ORCHARD DRIVE, #110, SILVER SPRING, MD 20904 | F3: TIME OF DAY: | I3: WEATHER: | N3: TEMP: | S3: JOB NAME:
F5: LOCATION: | P5: PE: | Q5: FALSE | S5: FOREMAN: ALFONSO
F6: APPROVED BY: | Q6: FALSE | S6: SUPER: OSCAR
A7: EMP # | B7: LABOR | E7: PHASE # | W7: TOTAL
B8: EMPLOYEE
B9: NAME:
B10: First | C10: Last | E10: CLASS # | G10: HOURS | I10: HOURS | K10: HOURS | M10: HOURS | O10: HOURS | Q10: HOURS | S10: HOURS | U10: HOURS | W10: HOURS
A11: =IFERROR(VLOOKUP(B11,'Employee Numbers'!A1:B125,2,FALSE),"") -> 177 | B11: Alfonso Muñoz | E11: 400 | W11: =SUM(G11:V12) -> 0
A13: =IFERROR(VLOOKUP(B13,'Employee Numbers'!A1:B125,2,FALSE),"") -> 1384 | B13: Gabriel Reyes | E13: 203 | W13: =SUM(G13:V14) -> 0
E14: 113
A15: =IFERROR(VLOOKUP(B15,'Employee Numbers'!A1:B125,2,FALSE),"") -> 1308 | B15: Epifanio Gutierrez | E15: 109 | W15: =SUM(G15:V16) -> 0
E16: 113
A17: =IFERROR(VLOOKUP(B17,'Employee Numbers'!A1:B125,2,FALSE),"") -> 1728 | B17: Edgar Muñoz-Torres | E17: 109 | W17: =SUM(G17:V18) -> 0
E18: 113
A19: =IFERROR(VLOOKUP(B19,'Employee Numbers'!A1:B125,2,FALSE),"") -> 1319 | B19: Javier Hugo Mendez | E19: 109 | W19: =SUM(G19:V20) -> 0
E20: 113
A21: =IFERROR(VLOOKUP(B21,'Employee Numbers'!A1:B125,2,FALSE),"") -> 1927 | B21: Jose Mejia Hernandez | E21: 121 | W21: =SUM(G21:V22) -> 0
E22: 113
A23: =IFERROR(VLOOKUP(B23,'Employee Numbers'!A1:B125,2,FALSE),"") -> 1021 | B23: Alfredo Perez-Vasquez | E23: 121 | W23: =SUM(G23:V24) -> 0
E24: 113
A25: =IFERROR(VLOOKUP(B25,'Employee Numbers'!A1:B125,2,FALSE),"") | B25: Fanny Reyes | E25: 208 | W25: =SUM(G25:V26) -> 0
E26: 113
A27: =IFERROR(VLOOKUP(B27,'Employee Numbers'!A1:B125,2,FALSE),"") -> 1171 | B27: Walter Navas | E27: 208 | W27: =SUM(G27:V28) -> 0
E28: 113
A29: =IFERROR(VLOOKUP(B29,'Employee Numbers'!A1:B125,2,FALSE),"") | W29: =SUM(G29:V30) -> 0
E30: 113
A31: =IFERROR(VLOOKUP(B31,'Employee Numbers'!A1:B125,2,FALSE),"") | B31: Daniel López | E31: 208 | W31: =SUM(G31:V32) -> 0
E32: 113
A33: =IFERROR(VLOOKUP(B33,'Employee Numbers'!A1:B125,2,FALSE),"") | B33: Walter castañada | E33: 208 | W33: =SUM(G33:V34) -> 0
E34: 113
B35: TOTAL | G35: =SUM(G11:H34) -> 0 | I35: =SUM(I11:J34) -> 0 | K35: =SUM(K11:L34) -> 0 | M35: =SUM(M11:N34) -> 0 | O35: =SUM(O11:P34) -> 0 | Q35: =SUM(Q11:R34) -> 0 | S35: =SUM(S11:T34) -> 0 | U35: =SUM(U11:V34) -> 0
A37: EQUIPMENT: | B37: EQUIP #'ER | C37: START HOURS | D37: STOP HOURS | G37: REG. | H37: S.B | I37: REG. | J37: S.B | K37: REG. | L37: S.B | M37: REG. | N37: S.B | O37: REG. | P37: S.B | Q37: REG. | R37: S.B | S37: REG. | T37: S.B | U37: S.B | W37: TOTAL
A38: Chevy | B38: 122 | W38: =SUM(G38:V38) -> 0
A39: Service Truck | B39: 302 | W39: =SUM(G39:V39) -> 0
A40: Mini Dump | B40: 412 | W40: =SUM(G40:V40) -> 0
A41: Backhoe | B41: 630 | W41: =SUM(G41:V41) -> 0
A42: Rolle | B42: 947 | W42: =SUM(G42:V42) -> 0
W43: =SUM(G43:V43) -> 0
W44: =SUM(G44:V44) -> 0
...

Sheet Data Sent
A1: Function | B1: Status
A2: Logged Superintendent Approval | B2: TRUE
A3: Logged PE Approval | B3: TRUE

Sheet Employee Numbers
A1: Javier Balmes | B1: 59
A2: Elmer Flores | B2: 77
A3: Jose Luis Herrera | B3: 91
A4: Jaime Herrera | B4: 92
A5: Narciso Herrera | B5: 95
A6: Salvador Pelaez | B6: 129
A7: Jose Dimas Delgado | B7: 146
A8: Adalberto Labastida | B8: 147
A9: Alfonso Muñoz | B9: 177
A10: Isidro Reyes Ortega | B10: 179
A11: Gaudencio Javier Ramirez | B11: 215
A12: Jose Mendez | B12: 285
... A125: Luciano De Miranda | B125: 2059

Sheet NVScriptsProperties
A1: autocratn | B1: autocratp
A2: dataSheetName | B2: "Timesheet"
A3: v | B3: "5.1"
A4: dataSheetId | B4: "1.320694942E9"
A5: updateTime | B5: "1.753352423013E12"
A6: vp | B6: "5.1"
A7: ssId | B7: "1AHWElLIpi23Mysmjc_seKEHkBP2oXD37jjJrgjOnU0o"

Sheet Data Valid.
A1: Admin | B1: Job_99 | C1: Job_1250 | D1: Job_1292 | E1: Job_1304 | F1: Job_1312 | G1: Job_1318 | H1: Job_1336 | I1: Job_1343 | J1: Job_1344 | K1: Job_1349 | L1: Job_1353 | M1: Job_1356 | N1: Job_1357 | O1: Job_1362 | P1: Job_1363 | Q1: Job_1364 | R1: Job_1368 | S1: Job_1369 | T1: Job_1370 | U1: Job_1371 | V1: Job_1372 | W1: Job_1378 | X1: Job_1379 | Y1: Job_1381 | Z1: Job_1382 | AA1: Job_1383 | AB1: Job_1386 | AE1: {=IF(Timesheet!S2=A1,INDIRECT("Admin"),IF(Timesheet!S2=B1,INDIRECT("Job_99"),IF(Timesheet!S2=C1,INDIRECT("Job_1250"),IF(Timesheet!S2=D1,INDIRECT("Job_1292"),IF(Timesheet!S2=E1,INDIRECT("Job_1304"),IF(Timesheet!S2=F1,INDIRECT("Job_1312"),IF(Timesheet!S2=G1,INDIRECT("Job_1318"),IF(Timesheet!S2=H1,INDIRECT("Job_1336"),IF(Timesheet!S2=I1,INDIRECT("Job_1343"),IF(Timesheet!S2=J1,INDIRECT("Job_1344"),IF(Timesheet!S2=K1,INDIRECT("Job_1349"),IF(Timesheet!S2=L1,INDIRECT("Job_1353"),IF(Timesheet!S2=M1,INDIRECT("Job_1356"),IF(Timesheet!S2=N1,INDIRECT("Job_1357"),IF(Timesheet!S2=O1,INDIRECT("Job_1362"),IF(Timesheet!S2=P1,INDIRECT("Job_1363"),IF(Timesheet!S2=Q1,INDIRECT("Job_1364"),IF(Timesheet!S2=R1,INDIRECT("Job_1368"),IF(Timesheet!S2=S1,INDIRECT("Job_1369"),IF(Timesheet!S2=T1,INDIRECT("Job_1370"),IF(Timesheet!S2=U1,INDIRECT("Job_1371"),IF(Timesheet!S2=V1,INDIRECT("Job_1372"),IF(Timesheet!S2=W1,INDIRECT("Job_1378"),IF(Timesheet!S2=X1,INDIRECT("Job_1379"),IF(Timesheet!S2=Y1,INDIRECT("Job_1381"),IF(Timesheet!S2=Z1,INDIRECT("Job_1382"),IF(Timesheet!S2=AA1,INDIRECT("Job_1383"),IF(Timesheet!S2=AB1,INDIRECT("Job_1386")))))))))))))))))))))))))))))} -> FALSE
A2: Admin | B2: Admin | C2: 130851 | D2: 476040 | E2: 585707 | F2: 120510 | G2: 476077 | H2: 114275 | I2: 110701 | J2: 130801 | K2: 130850 | L2: 130851 | M2: 505029 | N2: 130801 | O2: 110350 | P2: 110100 | Q2: 130850 | R2: 130850 | S2: 130801 | T2: 504590 | U2: 130801 | V2: 504593 | W2: 110350 | X2: 130801 | Y2: 130801 | Z2: 130851 | AA2: 120510 | AB2: 130801
A3: S&SL | B3: S&SL | C3: 585347 | D3: 476046 | E3: 120566 | F3: 120610 | G3: 476078 | H3: 120510 | I3: 110702 | J3: 697012 | K3: 120500 | L3: 655115 | M3: 505030 | N3: 504566 | O3: 130940 | P3: 110350 | Q3: 120500 | R3: 120510 | S3: 697012 | T3: 504591 | U3: 530160 | V3: 504591 | W3: 130940 | X3: 654098 | Y3: 120511 | Z3: 120515 | AA3: 120610 | AB3: 504500
A4: Vacation | B4: Vacation | C4: 585671 | D4: 476019 | E4: 120567 | F4: 120625 | G4: 476079 | H4: 120610 | I4: 110703 | J4: 655105 | K4: 505029 | L4: 655105 | M4: 562002 | N4: 504576 | O4: 120500 | P4: 130940 | Q4: 505029 | R4: 504724 | S4: 655105 | T4: 504559 | U4: 504593 | V4: 504594 | W4: 120500 | X4: 655120 | Y4: 110350 | Z4: 530161 | AA4: 120625 | AB4: 504525
C5: 120562 | D5: 476005 | E5: 120568 | F5: 114286 | G5: 17 | H5: 120625 | I5: 110704 | J5: 561170 | K5: 505030 | L5: 655393 | M5: 562003 | N5: 599201 | O5: 120610 | P5: 120500 | Q5: 505030 | R5: 504725 | S5: 655388 | T5: 201032 | U5: 504591 | V5: 504592 | W5: 120555 | X5: 634401 | Y5: 390542 | Z5: 504530 | AA5: 114286 | AB5: 530161
C6: 120572 | D6: 476002 | E6: 120610 | F6: 120820 | G6: 17C | H6: 120747 | I6: 110705 | J6: 655120 | K6: 504598 | L6: 561167 | M6: 634199 | N6: 599202 | O6: 114286 | P6: 114286 | Q6: 530160 | R6: 504726 | S6: 697010 | T6: 17 | U6: 504594 | V6: 17 | W6: 120562 | X6: 560107 | Y6: 110000 | Z6: 504560 | AA6: 114275 | AB6: 561201
C7: 387122 | D7: 476057 | E7: 120635 | F7: 199000 | G7: 17E | H7: 120820 | I7: 120510 | J7: 634401 | K7: 530160 | L7: 634352 | M7: 655011 | N7: 562301 | O7: 114249 | P7: 114249 | Q7: 562002 | R7: 571106 | S7: 620068 | T7: 17C | U7: 504592 | V7: 17C | W7: 120610 | X7: 634162 | Y7: 301122 | Z7: 562220 | AA7: 120820 | AB7: 504672
C8: 504566 | D8: 476056 | E8: 120747 | F8: 120747 | G8: 17O | H8: 120860 | I8: 130801 | J8: 634402 | K8: 634199 | L8: 17 | M8: 634419 | N8: 562302 | O8: 120860 | P8: 114266 | Q8: 562011 | R8: 585714 | S8: 561170 | T8: 17E | U8: 562413 | V8: 17E | W8: 114286 | X8: 719210 | Y8: 388135 | Z8: 562006 | AA8: 199000 | AB8: 561201
C9: 505033 | D9: 476061 | E9: 387131 | F9: 120860 | G9: 17P | H9: 199000 | I9: 504496 | J9: 634360 | K9: 655011 | L9: 17C | M9: 655125 | N9: 562303 | O9: 120746 | P9: 120860 | Q9: 562003 | R9: 585718 | S9: 655120 | T9: 17O | U9: 562414 | V9: 17O | W9: 114249 | X9: 561106 | Y9: 504523 | Z9: 562002 | AA9: 120747 | AB9: 655146
C10: 505034 | D10: 476060 | E10: 429737 | F10: 120785 | G10: 17T | H10: 202055 | I10: 504500 | J10: 634419 | K10: 17 | L10: 17E | M10: 17 | N10: 562304 | O10: 130941 | P10: 120746 | Q10: 634199 | R10: 114251 | S10: 634401 | T10: 17P | U10: 562415 | V10: 17P | W10: 114255 | X10: 17 | Y10: 504535 | Z10: 634402 | AA10: 120860 | AB10: 634204
C11: 505044 | D11: 476065 | E11: 456147 | F11: 120562 | G11: Admin | H11: 380201 | I11: 504560 | J11: 388051 | K11: 17C | L11: 17O | M11: 17C | N11: 634401 | O11: 120784 | P11: 130941 | Q11: 655011 | R11: 17 | S11: 634402 | T11: 17T | U11: 530161 | V11: 17T | W11: 114280 | X11: 17C | Y11: 504566 | Z11: 655105 | AA11: 120785 | AB11: 17
C12: 505045 | D12: 476064 | E12: 476000 | F12: 120563 | G12: S&SL | H12: 380205 | I12: 504561 | J12: 388051 | K12: 17E | L12: 17P | M12: 17E | N12: 561201 | O12: 130850 | P12: 120784 | Q12: 17 | R12: 17C | S12: 634360 | T12: Admin | U12: 562416 | V12: Admin | W12: 120784 | X12: 17E | Y12: 504581 | Z12: 655377 | AA12: 120784 | AB12: 17C
C13: 505046 | D13: 492738 | E13: 476012 | F13: 492654 | G13: Vacation | H13: 380218 | I13: 505033 | J13: 717001 | K13: 17O | L13: 17T | M13: 17O | N13: 561203 | O13: 130942 | P13: 130850 | Q13: 17C | R13: 17E | S13: 634419 | T13: S&SL | U13: 504619 | V13: S&SL | W13: 130941 | X13: 17O | Y13: 562012 | Z13: 655125 | AA13: 120800 | AB13: 17E
C14: 505048 | D14: 492654 | E14: 476018 | F14: 130841 | H14: 390687 | I14: 17 | J14: 390536 | K14: 17P | L14: Admin | M14: 17P | N14: 561163 | O14: 571200 | P14: 130942 | Q14: 17E | R14: 17O | S14: 388051 | T14: Vacation | U14: 561123 | V14: Vacation | W14: 130942 | X14: 17P | Y14: 562013 | Z14: 17 | AA14: 120555 | AB14: 17O
C15: 561139 | D15: 492728 | E15: 476019 | F15: 524525 | H15: 492654 | I15: 17C | J15: 799097 | K15: 17T | L15: S&SL | M15: 17T | N15: 561141 | O15: 201030 | P15: 210019 | Q15: 17O | R15: 17P | S15: 717001 | U15: 711214 | W15: 110800 | X15: 17T | Y15: 530160 | Z15: 17C | AA15: 120562 | AB15: 17P
C16: 561147 | D16: 492651 | E16: 476020 | F16: 202055 | H16: 504515 | I16: 17E | J16: 974008 | K16: Admin | L16: Vacation | M16: Admin | N16: 504570 | O16: 201032 | P16: 571200 | Q16: 17P | R16: 17T | S16: 390536 | U16: 17 | W16: 210019 | X16: Admin | Y16: 585405 | Z16: 17E | AA16: 120563 | AB16: 17T
C17: 561148 | D17: 17 | E17: 486120 | F17: 202056 | H17: 504516 | I17: 17O | J17: 110701 | K17: S&SL | M17: S&SL | N17: 504577 | O17: 301312 | P17: 201030 | Q17: 17T | R17: Admin | S17: 110701 | U17: 17C | W17: 571200 | X17: S&SL | Y17: 585412 | Z17: 17O | AA17: 492654 | AB17: Admin
C18: 561149 | D18: 17C | E18: 492655 | F18: 301010 | H18: 504546 | I18: 17P | J18: 110702 | K18: Vacation | M18: Vacation | N18: 599203 | O18: 380215 | P18: 201032 | Q18: Admin | R18: S&SL | S18: 110702 | U18: 17E | W18: 862102 | X18: Vacation | Y18: 585424 | Z18: 17P | AA18: 130841 | AB18: S&SL
C19: 561154 | D19: 17E | E19: 492664 | F19: 390341 | H19: 504550 | I19: 17T | J19: 110703 | N19: 599204 | O19: 380207 | P19: 301312 | Q19: S&SL | R19: Vacation | S19: 110703 | U19: 17O | W19: 380215 | Y19: 17 | Z19: 17T | AA19: 120630 | AB19: Vacation
C20: 561155 | D20: 17O | E20: 492665 | F20: 380205 | H20: 504558 | I20: Admin | J20: 110704 | N20: 562305 | O20: 380212 | P20: 380207 | Q20: Vacation | S20: 110704 | U20: 17P | W20: 380206 | Y20: 17C | Z20: Admin | AA20: 120631
C21: 561156 | D21: 17P | E21: 492675 | F21: 380218 | H21: 504564 | I21: S&SL | J21: 110705 | N21: 562306 | O21: 301322 | P21: 380212 | S21: 110705 | U21: 17T | W21: 380207 | Y21: 17E | Z21: S&SL | AA21: 120502
C22: 561157 | D22: 17T | E22: 492701 | F22: 524299 | H22: 504582 | I22: Vacation | J22: 634409 | N22: 634402 | O22: 388066 | P22: 301322 | S22: 17 | U22: Admin | W22: 380201 | Y22: 17O | Z22: Vacation | AA22: 201050
C23: 562400 | D23: Admin | E23: 492722 | F23: 504500 | H23: 504621 | J23: 130851 | N23: 561144 | O23: 520109 | P23: 388066 | S23: 17C | U23: S&SL | W23: 380212 | Y23: 17P | AA23: 202055
C24: 562401 | D24: S&SL | E24: 492723 | F24: 504530 | H24: 504624 | J24: 17 | N24: 561202 | O24: 520111 | P24: 520109 | S24: 17E | U24: Vacation | W24: 301322 | Y24: 17T | AA24: 203030
C25: 562402 | D25: Vacation | E25: 492724 | F25: 504511 | H25: 505050 | J25: 17C | N25: 561205 | O25: 520113 | P25: 520111 | S25: 17O | W25: 388066 | Y25: Admin | AA25: 201041
C26: 562403 | E26: 492726 | F26: 504541 | H26: 561106 | J26: 17E | N26: 561204 | O26: 524299 | P26: 520113 | S26: 17P | W26: 380209 | Y26: S&SL | AA26: 210030
C27: 562404 | E27: 492727 | F27: 504558 | H27: 571152 | J27: 17O | N27: 17 | O27: 504500 | P27: 524299 | S27: 17T | W27: 390321 | Y27: Vacation | AA27: 301010
C28: 562405 | E28: 492728 | F28: 504589 | H28: 585340 | J28: 17P | N28: 17C | O28: 504530 | P28: 504500 | S28: Admin | W28: 520114 | AA28: 301011
C29: 562406 | E29: 492729 | F29: 504564 | H29: 585342 | J29: 17T | N29: 17E | O29: 504560 | P29: 504530 | S29: S&SL | W29: 520109 | AA29: 301012
C30: 562407 | E30: 492730 | F30: 504582 | H30: 585361 | J30: Admin | N30: 17O | O30: 504513 | P30: 504560 | S30: Vacation | W30: 520111 | AA30: 390340
C31: 562408 | E31: 492738 | F31: 530161 | H31: 585405 | J31: S&SL | N31: 17P | O31: 504543 | P31: 504513 | W31: 520113 | AA31: 390341
C32: 562409 | E32: 504636 | F32: 599200 | H32: 585433 | J32: Vacation | N32: 17T | O32: 504600 | P32: 504543 | W32: 524299 | AA32: 301320
C33: 562410 | E33: 505051 | F33: 571206 | H33: 615582 | N33: Admin | O33: 530112 | P33: 504600 | W33: 504500 | AA33: 302515
C34: 562411 | E34: 505052 | F34: 561131 | H34: 616250 | N34: S&SL | O34: 561115 | P34: 530112 | W34: 504530 | AA34: 302518
C35: 562412 | E35: 505053 | F35: 585405 | H35: 616615 | N35: Vacation | O35: 562004 | P35: 561115 | W35: 504560 | AA35: 302521
C36: 585366 | E36: 505054 | F36: 585424 | H36: 634417 | O36: 571015 | P36: 571015 | W36: 504513 | AA36: 302524
C37: 585367 | E37: 505055 | F37: 585433 | H37: 634430 | O37: 571020 | P37: 571020 | W37: 504543 | AA37: 302527
C38: 585368 | E38: 505056 | F38: 585435 | H38: 634434 | O38: 812856 | P38: 812856 | W38: 504600 | AA38: 302530
C39: 585370 | E39: 505057 | F39: 585713 | H39: 634436 | O39: 812866 | P39: 812866 | W39: 530112 | AA39: 340014
C40: 585371 | E40: 505058 | F40: 585812 | H40: 634441 | O40: 812870 | P40: 812870 | W40: 561115 | AA40: 340015
...

Sheet W. Performed
A1: Vulcan | B1: Rowen | C1: Schuster - Rockville | D1: Schuster - Baltimore | E1: LaFarge | F1: M Luis Products | G1: MD Paving | H1: Pleasants | I1: Martin Marietta | J1: CD Thomas | K1: DC Materials | L1: People Ready | M1: Aggregate
A2: S Mix 2 | B2: S Mix 2 | C2: M Mix 3 | D2: S Mix 2 | E2: S Mix 2 | F2: 4.75mm | G2: 4.75mm | H2: 4.75mm | I2: #2 stone | J2: top soil | K2: top soil | M2: GAB
A3: S Mix 3 | B3: S Mix 3 | C3: M Mix 6 | D3: S Mix 3 | E3: S Mix 3 | F3: 9.5mm | G3: 9.5mm | H3: 9.5mm | I3: #8 stone | J3: c. borrow
A4: S Mix 6 | B4: S Mix 6 | C4: M Mix 9 | D4: S Mix 6 | E4: S Mix 6 | F4: 12.5mm | G4: 12.5mm | H4: 12.5mm | I4: #57 stone
A5: S Mix 9 | B5: S Mix 9 | D5: S Mix 9 | E5: S Mix 9 | F5: 19mm | G5: 19mm | H5: 19mm | I5: CR6
F6: 25mm | G6: 25mm | H6: 25mm | I6: R. Rapp
F7: cold patch | G7: cold patch | H7: cold patch | I7: GAB
I8: c. borrow
G20: {=IF(Timesheet!A49=A1,INDIRECT("Vulcan"),IF(Timesheet!A49=B1,INDIRECT("Rowen"),IF(Timesheet!A49=C1,INDIRECT("Schuster_Rockville"),IF(Timesheet!A49=D1,INDIRECT("Schuster_Baltimore"), IF(Timesheet!A49=E1, INDIRECT("LaFarge"),IF(Timesheet!A49=F1,INDIRECT("M_Luis_Products"),IF(Timesheet!A49=G1,INDIRECT("MD_Paving"),IF(Timesheet!A49=H1,INDIRECT("Pleasants"),IF(Timesheet!A49=I1,INDIRECT("Martin_Marietta"),IF(Timesheet!A49=J1,INDIRECT("CD_Thomas"),IF(Timesheet!A49=K1,INDIRECT("DC_Materials"), IF(Timesheet!A49=L1,INDIRECT("People_Ready"),IF(Timesheet!A49=M1,INDIRECT("Aggregate"))))))))))))))} -> FALSE | I20: {=IF(Timesheet!A50=A1,INDIRECT("Vulcan"),IF(Timesheet!A50=B1,INDIRECT("Rowen"),IF(Timesheet!A50=C1,INDIRECT("Schuster_Rockville"),IF(Timesheet!A50=D1,INDIRECT("Schuster_Baltimore"), IF(Timesheet!A50=E1, INDIRECT("LaFarge"),IF(Timesheet!A50=F1,INDIRECT("M_Luis_Products"),IF(Timesheet!A50=G1,INDIRECT("MD_Paving"),IF(Timesheet!A50=H1,INDIRECT("Pleasants"),IF(Timesheet!A50=I1,INDIRECT("Martin_Marietta"),IF(Timesheet!A50=J1,INDIRECT("CD_Thomas"),IF(Timesheet!A50=K1,INDIRECT("DC_Materials"), IF(Timesheet!A50=L1,INDIRECT("People_Ready"),IF(Timesheet!A50=M1,INDIRECT("Aggregate"))))))))))))))} -> FALSE | K20: {=IF(Timesheet!A51=A1,INDIRECT("Vulcan"),IF(Timesheet!A51=B1,INDIRECT("Rowen"),IF(Timesheet!A51=C1,INDIRECT("Schuster_Rockville"),IF(Timesheet!A51=D1,INDIRECT("Schuster_Baltimore"), IF(Timesheet!A51=E1, INDIRECT("LaFarge"),IF(Timesheet!A51=F1,INDIRECT("M_Luis_Products"),IF(Timesheet!A51=G1,INDIRECT("MD_Paving"),IF(Timesheet!A51=H1,INDIRECT("Pleasants"),IF(Timesheet!A51=I1,INDIRECT("Martin_Marietta"),IF(Timesheet!A51=J1,INDIRECT("CD_Thomas"),IF(Timesheet!A51=K1,INDIRECT("DC_Materials"), IF(Timesheet!A51=L1,INDIRECT("People_Ready"),IF(Timesheet!A51=M1,INDIRECT("Aggregate"))))))))))))))} -> FALSE | L20: {=IF(Timesheet!A52=A1,INDIRECT("Vulcan"),IF(Timesheet!A52=B1,INDIRECT("Rowen"),IF(Timesheet!A52=C1,INDIRECT("Schuster_Rockville"),IF(Timesheet!A52=D1,INDIRECT("Schuster_Baltimore"), IF(Timesheet!A52=E1, INDIRECT("LaFarge"),IF(Timesheet!A52=F1,INDIRECT("M_Luis_Products"),IF(Timesheet!A52=G1,INDIRECT("MD_Paving"),IF(Timesheet!A52=H1,INDIRECT("Pleasants"),IF(Timesheet!A52=I1,INDIRECT("Martin_Marietta"),IF(Timesheet!A52=J1,INDIRECT("CD_Thomas"),IF(Timesheet!A52=K1,INDIRECT("DC_Materials"), IF(Timesheet!A52=L1,INDIRECT("People_Ready"),IF(Timesheet!A52=M1,INDIRECT("Aggregate"))))))))))))))} -> FALSE | M20: {=IF(Timesheet!A53=A1,INDIRECT("Vulcan"),IF(Timesheet!A53=B1,INDIRECT("Rowen"),IF(Timesheet!A53=C1,INDIRECT("Schuster_Rockville"),IF(Timesheet!A53=D1,INDIRECT("Schuster_Baltimore"), IF(Timesheet!A53=E1, INDIRECT("LaFarge"),IF(Timesheet!A53=F1,INDIRECT("M_Luis_Products"),IF(Timesheet!A53=G1,INDIRECT("MD_Paving"),IF(Timesheet!A53=H1,INDIRECT("Pleasants"),IF(Timesheet!A53=I1,INDIRECT("Martin_Marietta"),IF(Timesheet!A53=J1,INDIRECT("CD_Thomas"),IF(Timesheet!A53=K1,INDIRECT("DC_Materials"), IF(Timesheet!A53=L1,INDIRECT("People_Ready"),IF(Timesheet!A53=M1,INDIRECT("Aggregate"))))))))))))))} -> FALSE

Sheet Complete Emails
A1: Email Address | B1: Name | C1: Date | D1: Complete
A2: walt.leizear@mluisconstruction.com | B2: Walt | C2: =Timesheet!D2 -> 0 | D2: =Timesheet!B74 -> FALSE
A3: oscar.allende@mluisconstruction.com | B3: Oscar | C3: =Timesheet!D2 -> 0 | D3: =Timesheet!B74 -> FALSE
A4: william.bratcher@mluisconstruction.com | B4: William | C4: =Timesheet!D2 -> 0 | D4: =Timesheet!B74 -> FALSE
A5: jason.leizear@mluisconstruction.com | B5: Jason | C5: =Timesheet!D2 -> 0 | D5: =Timesheet!B74 -> FALSE

Sheet Approved Emails
A1: Email Address | B1: Name | C1: Date | D1: Complete | E1: Approved
A2: schnelle.blanco@mluisconstruction.com | B2: Schnelle | C2: =Timesheet!D2 -> 0 | D2: =Timesheet!B74 -> FALSE | E2: =Timesheet!Q6 -> FALSE

Sheet Template
A1: {name}, Alfonso's timesheet for {date} has been submitted. Please click the following link to review: {link} To check if any material tickets have been uploaded for this timesheet, please click the following link: https://drive.google.com/drive/u/0/folders/19QOZnboOZroU0rTvfs-9G3uMdQEG9qro If approved, please fill out the 'Approved By' box with your name and check the box. Thanks, M. Luis IT
A2: {name}, Alfonso's timesheet for {date} has been submitted and approved. Thanks, M. Luis IT
